<?xml version="1.0"?>
<robot name="robot">

  <link name="root">
    <inertial>
      <mass value="0.1"/>
      <inertia ixx="0.0001" ixy="0.0" ixz="0.0" iyy="0.0001" iyz="0.0" izz="0.0001"/>
    </inertial>
  </link>

  <link name="hand">
    <visual>
      <geometry>
        <box size=".12 .12 0.02"/>
      </geometry>
    </visual>
    <collision>
      <geometry>
        <box size=".12 .12 0.02"/>
      </geometry>
    </collision>
    <inertial>
      <mass value="10"/>
      <inertia ixx="0.195" ixy="0.0" ixz="0.0" iyy="0.195" iyz="0.0" izz="0.375"/>
    </inertial>
  </link>

  <link name="virtual_0">
    <inertial>
      <mass value="0.1"/>
      <inertia ixx="0.0001" ixy="0.0" ixz="0.0" iyy="0.0001" iyz="0.0" izz="0.0001"/>
    </inertial>
  </link>
  <link name="virtual_1">
    <inertial>
      <mass value="0.1"/>
      <inertia ixx="0.0001" ixy="0.0" ixz="0.0" iyy="0.0001" iyz="0.0" izz="0.0001"/>
    </inertial>
  </link>

  <joint name="joint_0" type="prismatic">
    <parent link="root"/>
    <child link="virtual_0"/>
    <axis xyz="0 1 0"/>
    <limit lower="-1" upper="1" effort="1000" velocity="1.0"/>
    <dynamics damping="0.0" friction="0.0"/>
  </joint>

  <joint name="joint_1" type="prismatic">
    <parent link="virtual_0"/>
    <child link="virtual_1"/>
    <axis xyz="0 0 1"/>
    <limit lower="-1" upper="1" effort="1000" velocity="1.0"/>
  </joint>

  <joint name="joint_2" type="revolute">
    <parent link="virtual_1"/>
    <child link="hand"/>
    <axis xyz="1 0 0"/>
    <limit lower="-1.57" upper="1.57" effort="1000" velocity="1.0"/>
  </joint>

</robot>